<?xml version="1.0" ?>

<robot xmlns:xacro="http://www.ros.org/wiki/xacro" name="my_robot">

	<xacro:include filename="$(find my_robot)/urdf/my_robot.gazebo" />

	<link name="robot_footprint"></link>

	<joint name="robot_footprint_joint" type="fixed">
		<parent link="robot_footprint" />
		<child link="chassis" />
	</joint>

	<link name="chassis">
		<pose>
			0 0 0.1 0 0 0
		</pose>

		<inertial>
			<mass value="15.0" />
			<origin xyz="0 0 0" rpy="0 0 0" />
			<inertia ixx="0.1" ixy="0" ixz="0" iyy="0.1" iyz="0" izz="0.1" />
		</inertial>

		<collision name="collision">
			<geometry>
				<box size="0.4 0.4 0.1" />
			</geometry>
			<origin xyz="0 0 0" rpy="0 0 0" />
		</collision>

		<visual name="chassis_visual">
			<geometry>
				<box size="0.4 0.4 0.1" />
			</geometry>
			<origin xyz="0 0 0" rpy="0 0 0" />
		</visual>

		<collision name="back_caster_collision">
			<geometry>
				<sphere radius="0.05" />
			</geometry>
			<origin xyz="-0.15 0 -0.05" rpy="0 0 0" />
		</collision>

		<visual name="back_caster_visual">
			<geometry>
				<sphere radius="0.05" />
			</geometry>
			<origin xyz="-0.15 0 -0.05" rpy="0 0 0" />
		</visual>

		<collision name="front_caster_collision">
			<geometry>
				<sphere radius="0.05" />
			</geometry>
			<origin xyz="0.15 0 -0.05" rpy="0 0 0" />
		</collision>

		<visual name="front_caster_visual">
			<geometry>
				<sphere radius="0.05" />
			</geometry>
			<origin xyz="0.15 0 -0.05" rpy="0 0 0" />
		</visual>

	</link>

	<joint name="left_wheel_hinge" type="continuous">
		<parent link="chassis" />
		<child link="left_wheel" />
		<origin xyz="0 -0.25 0" rpy="0 0 0" />
		<axis xyz="0 1 0" rpy="0 0 0" />
		<limit effort="10000" velocity="1000" />
		<dynamics damping="1.0" friction="1.0" />
	</joint>

	<link name="left_wheel">

		<inertial>
			<origin xyz="0 0 0" rpy="0 0 0" />
			<mass value="5" />
			<inertia ixx="0.1" ixy="0" ixz="0" iyy="0.1" iyz="0" izz="0.1" />
		</inertial>

		<collision name="left_wheel_collision">
			<geometry>
				<cylinder length="0.05" radius="0.1" />
			</geometry>
			<origin xyz="0 0 0" rpy="0 1.57 1.57" />
		</collision>

		<visual name="left_wheel_visual">
			<geometry>
				<cylinder length="0.05" radius="0.1" />
			</geometry>
			<origin xyz="0 0 0" rpy="0 1.57 1.57" />
		</visual>

	</link>

	<joint name="right_wheel_hinge" type="continuous">
		<parent link="chassis" />
		<child link="right_wheel" />
		<origin xyz="0 0.25 0" rpy="0 0 0" />
		<axis xyz="0 1 0" rpy="0 0 0" />
		<limit effort="10000" velocity="1000" />
		<dynamics damping="1.0" friction="1.0" />
	</joint>

	<link name="right_wheel">

		<inertial>
			<origin xyz="0 0 0" rpy="0 0 0" />
			<mass value="5" />
			<inertia ixx="0.1" ixy="0" ixz="0" iyy="0.1" iyz="0" izz="0.1" />
		</inertial>

		<collision name="right_wheel_collision">
			<geometry>
				<cylinder length="0.05" radius="0.1" />
			</geometry>
			<origin xyz="0 0 0" rpy="0 1.57 1.57" />
		</collision>

		<visual name="right_wheel_visual">
			<geometry>
				<cylinder length="0.05" radius="0.1" />
			</geometry>
			<origin xyz="0 0 0" rpy="0 1.57 1.57" />
		</visual>

	</link>

	<joint name="body_joint" type="fixed">
		<parent link="chassis" />
		<child link="body" />
		<origin xyz="0 0 0.22" rpy="0 0 0" />
		<axis xyz="0 0 1" rpy="0 0 0" />
	</joint>

	<link name="body">

		<inertial>
			<origin xyz="0 0 0" rpy="0 0 0" />
			<mass value="3" />
			<inertia ixx="0.1" ixy="0" ixz="0" iyy="0.1" iyz="0" izz="0.1" />
		</inertial>

		<collision name="body_collision">
			<geometry>
				<box size="0.25 0.35 0.4" />
			</geometry>
			<origin xyz="0 0 0" rpy="0 0 0" />
		</collision>

		<visual name="body_visual">
			<geometry>
				<box size="0.25 0.35 0.4" />
			</geometry>
			<origin xyz="0 0 0" rpy="0 0 0" />
		</visual>

	</link>

	<joint name="head_joint" type="fixed">
		<parent link="body" />
		<child link="head" />
		<origin xyz="0 0 0.25" rpy="0 0 0" />
		<axis xyz="0 0 1" rpy="0 0 0" />
	</joint>

	<link name="head">

		<inertial>
			<origin xyz="0 0 0" rpy="0 0 0" />
			<mass value="2" />
			<inertia ixx="0.05" ixy="0" ixz="0" iyy="0.05" iyz="0" izz="0.05" />
		</inertial>

		<collision name="head_collision">
			<geometry>
				<box size="0.2 0.38 0.2" />
			</geometry>
			<origin xyz="0 0 0" rpy="0 0 0" />
		</collision>

		<visual name="head_visual">
			<geometry>
				<box size="0.2 0.38 0.2" />
			</geometry>
			<origin xyz="0 0 0" rpy="0 0 0" />
		</visual>

		<collision name="left_eye_collision">
			<geometry>
				<sphere radius="0.03" />
			</geometry>
			<origin xyz="0.08 -0.09 0.05" rpy="0 0 0" />
		</collision>

		<visual name="left_eye_visual">
			<geometry>
				<sphere radius="0.03" />
			</geometry>
			<origin xyz="0.08 -0.09 0.05" rpy="0 0 0" />
		</visual>

		<collision name="right_eye_collision">
			<geometry>
				<sphere radius="0.03" />
			</geometry>
			<origin xyz="0.08 0.09 0.05" rpy="0 0 0" />
		</collision>

		<visual name="right_eye_visual">
			<geometry>
				<sphere radius="0.03" />
			</geometry>
			<origin xyz="0.08 0.09 0.05" rpy="0 0 0" />
		</visual>

		<collision name="mouth_collision">
			<geometry>
				<box size="0.045 0.06 0.01" />
			</geometry>
			<origin xyz="0.08 0 -0.02" rpy="0 0 0" />
		</collision>

		<visual name="mouth_visual">
			<geometry>
				<box size="0.045 0.06 0.01" />
			</geometry>
			<origin xyz="0.08 0 -0.02" rpy="0 0 0" />
		</visual>


	</link>

	<joint name="camera_joint" type="fixed">
		<parent link="body" />
		<child link="camera" />
		<axis xyz="0 1 0" rpy="0 0 0" />
		<origin xyz="0.11 0 0" rpy="0 0 0" />
	</joint>

	<link name="camera">

		<inertial>
			<origin xyz="0 0 0" rpy="0 0 0" />
			<mass value="0.1" />
			<inertia ixx="1e-6" ixy="0" ixz="0" iyy="1e-6" iyz="0" izz="1e-6" />
		</inertial>

		<collision name="camera_collision">
			<geometry>
				<sphere radius="0.04" />
			</geometry>
			<origin xyz="0 0 0" rpy="0 0 0" />
		</collision>

		<visual name="camera_visual">
			<geometry>
				<sphere radius="0.04" />
			</geometry>
			<origin xyz="0 0 0" rpy="0 0 0" />
		</visual>

	</link>

	<joint name="lidar_joint" type="fixed">
		<parent link="head" />
		<child link="lidar" />
		<axis xyz="0 1 0" rpy="0 0 0" />
		<origin xyz="0 0 0.12" rpy="0 0 0" />
	</joint>

	<link name="lidar">

		<inertial>
			<origin xyz="0 0 0" rpy="0 0 0" />
			<mass value="1e-5" />
			<inertia ixx="1e-6" ixy="0" ixz="0" iyy="1e-6" iyz="0" izz="1e-6" />
		</inertial>

		<collision name="lidar_collision">
			<geometry>
				<box size="0.05 0.05 0.05" />
			</geometry>
			<origin xyz="0 0 0" rpy="0 0 0" />
		</collision>

		<visual name="lidar_visual">
			<geometry>
				<mesh filename="package://my_robot/meshes/hokuyo.dae" />
			</geometry>
			<origin xyz="0 0 0" rpy="0 0 0" />
		</visual>

	</link>

</robot>